Workbook

Sheet Sheet1
A1: Id | B1: وقت البدء | C1: وقت الإكمال | D1: البريد الإلكتروني | E1: الاسم | F1: ما هو جنسك؟ | G1: ما هو تخصصك؟ | H1: الدرجة الجامعية : | I1: ما هي سنتك الدراسية؟ | J1: مكان السكن؟ | K1: جامعتك خاصة أم حكومية؟ | L1: هل سبق لك استخدام أدوات انشاء النصوص باستخدام الذكاء الاصطناعي؟ | M1: كم مدى استخدام أدوات انشاء النصوص باستخدام الذكاء الاصطناعي لأغراض الدراسية؟ | N1: هل تستخدم أدوات انشاء النصوص باستخدام الذكاء الاصطناعي كبديل للبحث التقليدي؟ | O1: هل تشعر أن مهاراتك التحليلية وقدرتك على حل المسائل تأثرت بسبب استخدام أدوات إنشاء النصوص باستخدام الذكاء الاصطناعي؟ | P1: هل تساعدك أدوات إنشاء النصوص باستخدام الذكاء الاصطناعي على التعلم بشكل مستقل؟ | Q1: هل تقلل أدوات إنشاء النصوص باستخدام الذكاء الاصطناعي من دافعيتك للدراسة أم العكس؟ | R1: هل تشعر أنك تعتمد على أدوات انشاء النصوص باستخدام الذكاء الاصطناعي أكثر من اللازم بدلا عن التفكير بنفسك؟ | S1: هل تعتقد أن استخدام أدوات انشاء النصوص باستخدام الذكاء الاصطناعي في حل المشاريع /الواجبات يعتبر غشا؟ | T1: هل سبق لك تسليم مشروع كامل باستخدام أدوات انشاء النصوص باستخدام الذكاء الاصطناعي؟ | U1: هل تم مراجعة المحتوى ومراجع المحتوى بعد انشاءه؟ | V1: هل واجهت بعض الأخطاء في المحتوى؟ | W1: هل سبق لك استخدام أدوات انشاء النصوص باستخدام الذكاء الاصطناعي في حل الامتحانات داخل القاعة الجامعية؟ | X1: هل يوفر الذكاء الاصطناعي من وقتك أثناء الدراسة؟ | Y1: هل سبق اتهامك او تنبيهك من قبل أحد الأساتذة بشأن استخدام أدوات انشاء النصوص باستخدام الذكاء الاصطناعي في واجب أو مشروع؟ | Z1: بالإشارة إلى السؤال السابق، هل كان المدرس على حق؟ | AA1: ما مدى معرفتك بكيفية عمل أدوات كشف استخدام أدوات انشاء النصوص باستخدام الذكاء الاصطناعي؟ | AB1: هل تعتقد أن من السهل على الأساتذة اكتشاف استخدام أدوات انشاء النصوص باستخدام الذكاء الاصطناعي؟ | AC1: ما هو أكثر أداة ذكاء اصطناعي تستخدمها؟ | AD1: هل تعتقد أن أدوات انشاء النصوص باستخدام الذكاء الاصطناعي حسن من التعليم في الأعوام الماضية؟ | AE1: هل تستخدم أدوات إنشاء النصوص باستخدام الذكاء الاصطناعي كبديل لمحركات البحث ( google, yahoo, etc) والبحث التقليدي في المراجع والكتب؟ | AF1: ما هي النصائح لاستخدام أدوات إنشاء النصوص باستخدام الذكاء الاصطناعي بطريقة ايجابية؟ | AG1: هل تعلمت أو بحثت في أفضل الطرق لصياغة الأسئلة لمواجهة لأدوات إنشاء النصوص باستخدام الذكاء الاصطناعي؟ | AH1: Drop_Risk_Score | AI1: Drop_Class_Label (proxy: 1=drop, 0=no)
A2: 1 | B2: 46158.757 | C2: 46158.764 | D2: anonymous | F2: انثى | G2: تخصصات هندسية وتقنية | H2: بكالوريوس | I2: الخامسة فأعلى | J2: لواء | K2: حكومية | L2: نعم | M2: غالبًا | N2: دائمًا | O2: تأثرت بشكل سلبي | P2: نعم | Q2: لا تؤثر | R2: نعم | S2: يعتمد على طريقة الاستخدام | T2: لا | U2: أحيانًا | V2: أحيانًا | W2: لا | X2: لا | Y2: لا | Z2: أجبت السؤال السابق ب"لا" | AA2: ضعيفة | AB2: أحيانًا | AC2: ChatGPT;Google Gemini; | AD2: لا | AE2: دائمًا | AF2: ما عندي | AG2: لا | AH2: =(O2='Labeling Rules'!$C$6)*'Labeling Rules'!$D$6+(Q2='Labeling Rules'!$C$7)*'Labeling Rules'!$D$7+(R2='Labeling Rules'!$C$8)*'Labeling Rules'!$D$8+(R2='Labeling Rules'!$C$9)*'Labeling Rules'!$D$9+(P2='Labeling Rules'!$C$10)*'Labeling Rules'!$D$10+(M2='Labeling Rules'!$C$11)*'Labeling Rules'!$D$11+(T2='Labeling Rules'!$C$12)*'Labeling Rules'!$D$12+(U2='Labeling Rules'!$C$13)*'Labeling Rules'!$D$13+(W2='Labeling Rules'!$C$14)*'Labeling Rules'!$D$14+(Y2='Labeling Rules'!$C$15)*'Labeling Rules'!$D$15 -> 4 | AI2: =IF(AH2>='Labeling Rules'!$D$17,1,0) -> 0
A3: 2 | B3: 46158.88 | C3: 46158.882 | D3: anonymous | F3: انثى | G3: تخصصات هندسية وتقنية | H3: بكالوريوس | I3: الثالثة | J3: العاصمة | K3: حكومية | L3: نعم | M3: غالبًا | N3: دائمًا | O3: لم تتأثر | P3: نعم | Q3: تزيد الدافعية | R3: نعم | S3: يعتمد على طريقة الاستخدام | T3: لا | U3: دائمًا | V3: أحيانًا | W3: لا | X3: نعم بشكل كبير | Y3: لا | Z3: أجبت السؤال السابق ب"لا" | AA3: ممتازة | AB3: نعم | AC3: Google Gemini;ChatGPT; | AD3: نعم | AE3: أحيانًا | AF3: . | AG3: . | AH3: =(O3='Labeling Rules'!$C$6)*'Labeling Rules'!$D$6+(Q3='Labeling Rules'!$C$7)*'Labeling Rules'!$D$7+(R3='Labeling Rules'!$C$8)*'Labeling Rules'!$D$8+(R3='Labeling Rules'!$C$9)*'Labeling Rules'!$D$9+(P3='Labeling Rules'!$C$10)*'Labeling Rules'!$D$10+(M3='Labeling Rules'!$C$11)*'Labeling Rules'!$D$11+(T3='Labeling Rules'!$C$12)*'Labeling Rules'!$D$12+(U3='Labeling Rules'!$C$13)*'Labeling Rules'!$D$13+(W3='Labeling Rules'!$C$14)*'Labeling Rules'!$D$14+(Y3='Labeling Rules'!$C$15)*'Labeling Rules'!$D$15 -> 2 | AI3: =IF(AH3>='Labeling Rules'!$D$17,1,0) -> 0
A4: 3 | B4: 46158.88 | C4: 46158.884 | D4: anonymous | F4: ذكر | G4: تخصصات هندسية وتقنية | H4: بكالوريوس | I4: الرابعة | J4: محافظة | K4: حكومية | L4: نعم | M4: دائمًا | N4: غالبًا | O4: تأثرت بشكل إيجابي | P4: نعم | Q4: لا تؤثر | R4: لا | S4: يعتمد على طريقة الاستخدام | T4: لا | U4: دائمًا | V4: أحيانًا | W4: لا | X4: نعم بشكل كبير | Y4: لا | Z4: أجبت السؤال السابق ب"لا" | AA4: جيدة | AB4: أحيانًا | AC4: ChatGPT; | AD4: نعم | AE4: أحيانًا | AF4: . | AG4: . | AH4: =(O4='Labeling Rules'!$C$6)*'Labeling Rules'!$D$6+(Q4='Labeling Rules'!$C$7)*'Labeling Rules'!$D$7+(R4='Labeling Rules'!$C$8)*'Labeling Rules'!$D$8+(R4='Labeling Rules'!$C$9)*'Labeling Rules'!$D$9+(P4='Labeling Rules'!$C$10)*'Labeling Rules'!$D$10+(M4='Labeling Rules'!$C$11)*'Labeling Rules'!$D$11+(T4='Labeling Rules'!$C$12)*'Labeling Rules'!$D$12+(U4='Labeling Rules'!$C$13)*'Labeling Rules'!$D$13+(W4='Labeling Rules'!$C$14)*'Labeling Rules'!$D$14+(Y4='Labeling Rules'!$C$15)*'Labeling Rules'!$D$15 -> 1 | AI4: =IF(AH4>='Labeling Rules'!$D$17,1,0) -> 0
A5: 4 | B5: 46158.882 | C5: 46158.884 | D5: anonymous | F5: ذكر | G5: تخصصات علمية | H5: بكالوريوس | I5: الرابعة | J5: العاصمة | K5: حكومية | L5: نعم | M5: دائمًا | N5: غالبًا | O5: تأثرت بشكل إيجابي | P5: نعم | Q5: تزيد الدافعية | R5: أحيانًا | S5: يعتمد على طريقة الاستخدام | T5: نعم | U5: أحيانًا | V5: أحيانًا | W5: لا | X5: نعم بشكل كبير | Y5: نعم | Z5: نعم | AA5: ممتازة | AB5: نعم | AC5: Google Gemini;Claude; | AD5: نعم | AE5: أحيانًا | AF5: عدم الاعتماد عليها بشكل كلي حتى لا تنعدم مهاراتك بشكل كامل | AG5: لا الصراحة | AH5: =(O5='Labeling Rules'!$C$6)*'Labeling Rules'!$D$6+(Q5='Labeling Rules'!$C$7)*'Labeling Rules'!$D$7+(R5='Labeling Rules'!$C$8)*'Labeling Rules'!$D$8+(R5='Labeling Rules'!$C$9)*'Labeling Rules'!$D$9+(P5='Labeling Rules'!$C$10)*'Labeling Rules'!$D$10+(M5='Labeling Rules'!$C$11)*'Labeling Rules'!$D$11+(T5='Labeling Rules'!$C$12)*'Labeling Rules'!$D$12+(U5='Labeling Rules'!$C$13)*'Labeling Rules'!$D$13+(W5='Labeling Rules'!$C$14)*'Labeling Rules'!$D$14+(Y5='Labeling Rules'!$C$15)*'Labeling Rules'!$D$15 -> 4 | AI5: =IF(AH5>='Labeling Rules'!$D$17,1,0) -> 0
A6: 5 | B6: 46158.881 | C6: 46158.884 | D6: anonymous | F6: انثى | G6: تخصصات طبية | H6: بكالوريوس | I6: الرابعة | J6: العاصمة | K6: حكومية | L6: نعم | M6: نادرًا | N6: أبدًا | O6: لم تتأثر | P6: إلى حد ما | Q6: لا تؤثر | R6: لا | S6: نعم | T6: لا | U6: دائمًا | V6: أحيانًا | W6: لا | X6: إلى حد ما | Y6: لا | Z6: أجبت السؤال السابق ب"لا" | AA6: متوسطة | AB6: نعم | AC6: Google Gemini; | AD6: لا | AE6: نادرًا | AF6: تحديد مواضيع و تفصيلهم بشكل دقيق | AG6: لا | AH6: =(O6='Labeling Rules'!$C$6)*'Labeling Rules'!$D$6+(Q6='Labeling Rules'!$C$7)*'Labeling Rules'!$D$7+(R6='Labeling Rules'!$C$8)*'Labeling Rules'!$D$8+(R6='Labeling Rules'!$C$9)*'Labeling Rules'!$D$9+(P6='Labeling Rules'!$C$10)*'Labeling Rules'!$D$10+(M6='Labeling Rules'!$C$11)*'Labeling Rules'!$D$11+(T6='Labeling Rules'!$C$12)*'Labeling Rules'!$D$12+(U6='Labeling Rules'!$C$13)*'Labeling Rules'!$D$13+(W6='Labeling Rules'!$C$14)*'Labeling Rules'!$D$14+(Y6='Labeling Rules'!$C$15)*'Labeling Rules'!$D$15 -> 0 | AI6: =IF(AH6>='Labeling Rules'!$D$17,1,0) -> 0
A7: 6 | B7: 46158.882 | C7: 46158.885 | D7: anonymous | F7: انثى | G7: تخصصات طبية | H7: بكالوريوس | I7: الثانية | J7: العاصمة | K7: حكومية | L7: نعم | M7: نادرًا | N7: دائمًا | O7: تأثرت بشكل سلبي | P7: إلى حد ما | Q7: تقلل الدافعية | R7: أحيانًا | S7: لا | T7: لا | U7: أحيانًا | V7: كثيرًا | W7: لا | X7: نعم بشكل كبير | Y7: نعم | Z7: جزئيًا | AA7: جيدة | AB7: أحيانًا | AC7: Google Gemini;Microsoft Copilot;NoteLM; | AD7: إلى حد ما | AE7: أحيانًا | AF7: تحديد الغاية و الهدف من كل سؤال تساله للذكاء الاصطناعي كي لا يبحث في مواضيع خارجة عن اهتمامك | AG7: نعم (تعلمت بالطريقة الصعبة) | AH7: =(O7='Labeling Rules'!$C$6)*'Labeling Rules'!$D$6+(Q7='Labeling Rules'!$C$7)*'Labeling Rules'!$D$7+(R7='Labeling Rules'!$C$8)*'Labeling Rules'!$D$8+(R7='Labeling Rules'!$C$9)*'Labeling Rules'!$D$9+(P7='Labeling Rules'!$C$10)*'Labeling Rules'!$D$10+(M7='Labeling Rules'!$C$11)*'Labeling Rules'!$D$11+(T7='Labeling Rules'!$C$12)*'Labeling Rules'!$D$12+(U7='Labeling Rules'!$C$13)*'Labeling Rules'!$D$13+(W7='Labeling Rules'!$C$14)*'Labeling Rules'!$D$14+(Y7='Labeling Rules'!$C$15)*'Labeling Rules'!$D$15 -> 6 | AI7: =IF(AH7>='Labeling Rules'!$D$17,1,0) -> 1
A8: 7 | B8: 46158.882 | C8: 46158.885 | D8: anonymous | F8: ذكر | G8: تخصصات علمية | H8: بكالوريوس | I8: الرابعة | J8: العاصمة | K8: حكومية | L8: نعم | M8: دائمًا | N8: دائمًا | O8: تأثرت بشكل إيجابي | P8: نعم | Q8: تزيد الدافعية | R8: نعم | S8: نعم | T8: نعم | U8: دائمًا | V8: كثيرًا | W8: نعم | X8: نعم بشكل كبير | Y8: نعم | Z8: نعم | AA8: ممتازة | AB8: نعم | AC8: ChatGPT;Claude; | AD8: نعم | AE8: دائمًا | AF8: الاقتباس منها وعدم اخذ النص بالكامل | AG8: لا | AH8: =(O8='Labeling Rules'!$C$6)*'Labeling Rules'!$D$6+(Q8='Labeling Rules'!$C$7)*'Labeling Rules'!$D$7+(R8='Labeling Rules'!$C$8)*'Labeling Rules'!$D$8+(R8='Labeling Rules'!$C$9)*'Labeling Rules'!$D$9+(P8='Labeling Rules'!$C$10)*'Labeling Rules'!$D$10+(M8='Labeling Rules'!$C$11)*'Labeling Rules'!$D$11+(T8='Labeling Rules'!$C$12)*'Labeling Rules'!$D$12+(U8='Labeling Rules'!$C$13)*'Labeling Rules'!$D$13+(W8='Labeling Rules'!$C$14)*'Labeling Rules'!$D$14+(Y8='Labeling Rules'!$C$15)*'Labeling Rules'!$D$15 -> 6 | AI8: =IF(AH8>='Labeling Rules'!$D$17,1,0) -> 1
A9: 8 | B9: 46158.884 | C9: 46158.886 | D9: anonymous | F9: ذكر | G9: تخصصات هندسية وتقنية | H9: بكالوريوس | I9: الرابعة | J9: العاصمة | K9: حكومية | L9: نعم | M9: غالبًا | N9: غالبًا | O9: تأثرت بشكل سلبي | P9: إلى حد ما | Q9: تزيد الدافعية | R9: نعم | S9: يعتمد على طريقة الاستخدام | T9: نعم | U9: أحيانًا | V9: أحيانًا | W9: لا | X9: نعم بشكل كبير | Y9: نعم | Z9: جزئيًا | AA9: متوسطة | AB9: نعم | AC9: ChatGPT; | AD9: إلى حد ما | AE9: أحيانًا | AF9: لا تعتمد عليها 100% | AG9: لا | AH9: =(O9='Labeling Rules'!$C$6)*'Labeling Rules'!$D$6+(Q9='Labeling Rules'!$C$7)*'Labeling Rules'!$D$7+(R9='Labeling Rules'!$C$8)*'Labeling Rules'!$D$8+(R9='Labeling Rules'!$C$9)*'Labeling Rules'!$D$9+(P9='Labeling Rules'!$C$10)*'Labeling Rules'!$D$10+(M9='Labeling Rules'!$C$11)*'Labeling Rules'!$D$11+(T9='Labeling Rules'!$C$12)*'Labeling Rules'!$D$12+(U9='Labeling Rules'!$C$13)*'Labeling Rules'!$D$13+(W9='Labeling Rules'!$C$14)*'Labeling Rules'!$D$14+(Y9='Labeling Rules'!$C$15)*'Labeling Rules'!$D$15 -> 6 | AI9: =IF(AH9>='Labeling Rules'!$D$17,1,0) -> 1
A10: 9 | B10: 46158.885 | C10: 46158.887 | D10: anonymous | F10: انثى | G10: تخصصات علمية | H10: بكالوريوس | I10: الرابعة | J10: العاصمة | K10: حكومية | L10: نعم | M10: غالبًا | N10: أبدًا | O10: لم تتأثر | P10: إلى حد ما | Q10: لا تؤثر | R10: لا | S10: يعتمد على طريقة الاستخدام | T10: لا | U10: دائمًا | V10: أحيانًا | W10: لا | X10: إلى حد ما | Y10: لا | Z10: أجبت السؤال السابق ب"لا" | AA10: متوسطة | AB10: أحيانًا | AC10: Google Gemini; | AD10: لا | AE10: أبدًا | AF10: عدم الاعتماد عليها بشكل مبالغ فيه | AG10: لا لم ابحث | AH10: =(O10='Labeling Rules'!$C$6)*'Labeling Rules'!$D$6+(Q10='Labeling Rules'!$C$7)*'Labeling Rules'!$D$7+(R10='Labeling Rules'!$C$8)*'Labeling Rules'!$D$8+(R10='Labeling Rules'!$C$9)*'Labeling Rules'!$D$9+(P10='Labeling Rules'!$C$10)*'Labeling Rules'!$D$10+(M10='Labeling Rules'!$C$11)*'Labeling Rules'!$D$11+(T10='Labeling Rules'!$C$12)*'Labeling Rules'!$D$12+(U10='Labeling Rules'!$C$13)*'Labeling Rules'!$D$13+(W10='Labeling Rules'!$C$14)*'Labeling Rules'!$D$14+(Y10='Labeling Rules'!$C$15)*'Labeling Rules'!$D$15 -> 0 | AI10: =IF(AH10>='Labeling Rules'!$D$17,1,0) -> 0
A11: 10 | B11: 46158.887 | C11: 46158.888 | D11: anonymous | F11: ذكر | G11: تخصصات هندسية وتقنية | H11: بكالوريوس | I11: الرابعة | J11: العاصمة | K11: حكومية | L11: نعم | M11: دائمًا | N11: غالبًا | O11: لم تتأثر | P11: نعم | Q11: لا تؤثر | R11: أحيانًا | S11: لا | T11: نعم | U11: دائمًا | V11: نادرًا | W11: لا | X11: نعم بشكل كبير | Y11: لا | Z11: أجبت السؤال السابق ب"لا" | AA11: ممتازة | AB11: أحيانًا | AC11: Claude; | AD11: نعم | AE11: دائمًا | AF11: N | AG11: Yes | AH11: =(O11='Labeling Rules'!$C$6)*'Labeling Rules'!$D$6+(Q11='Labeling Rules'!$C$7)*'Labeling Rules'!$D$7+(R11='Labeling Rules'!$C$8)*'Labeling Rules'!$D$8+(R11='Labeling Rules'!$C$9)*'Labeling Rules'!$D$9+(P11='Labeling Rules'!$C$10)*'Labeling Rules'!$D$10+(M11='Labeling Rules'!$C$11)*'Labeling Rules'!$D$11+(T11='Labeling Rules'!$C$12)*'Labeling Rules'!$D$12+(U11='Labeling Rules'!$C$13)*'Labeling Rules'!$D$13+(W11='Labeling Rules'!$C$14)*'Labeling Rules'!$D$14+(Y11='Labeling Rules'!$C$15)*'Labeling Rules'!$D$15 -> 3 | AI11: =IF(AH11>='Labeling Rules'!$D$17,1,0) -> 0
A12: 11 | B12: 46158.887 | C12: 46158.889 | D12: anonymous | F12: ذكر | G12: تخصصات علمية | H12: بكالوريوس | I12: الرابعة | J12: العاصمة | K12: حكومية | L12: نعم | M12: غالبًا | N12: دائمًا | O12: لم تتأثر | P12: نعم | Q12: لا تؤثر | R12: أحيانًا | S12: لا | T12: نعم | U12: أحيانًا | V12: أحيانًا | W12: نعم | X12: نعم بشكل كبير | Y12: لا | Z12: أجبت السؤال السابق ب"لا" | AA12: ممتازة | AB12: نعم | AC12: Claude;ChatGPT;Google Gemini; | AD12: إلى حد ما | AE12: نادرًا | AF12: استخدامها بطريقة سليمة ولا مانع من استخدامها في الواجبات والبحوث | AG12: نعم | AH12: =(O12='Labeling Rules'!$C$6)*'Labeling Rules'!$D$6+(Q12='Labeling Rules'!$C$7)*'Labeling Rules'!$D$7+(R12='Labeling Rules'!$C$8)*'Labeling Rules'!$D$8+(R12='Labeling Rules'!$C$9)*'Labeling Rules'!$D$9+(P12='Labeling Rules'!$C$10)*'Labeling Rules'!$D$10+(M12='Labeling Rules'!$C$11)*'Labeling Rules'!$D$11+(T12='Labeling Rules'!$C$12)*'Labeling Rules'!$D$12+(U12='Labeling Rules'!$C$13)*'Labeling Rules'!$D$13+(W12='Labeling Rules'!$C$14)*'Labeling Rules'!$D$14+(Y12='Labeling Rules'!$C$15)*'Labeling Rules'!$D$15 -> 3 | AI12: =IF(AH12>='Labeling Rules'!$D$17,1,0) -> 0
A13: 12 | B13: 46158.89 | C13: 46158.892 | D13: anonymous | F13: انثى | G13: تخصصات هندسية وتقنية | H13: بكالوريوس | I13: الرابعة | J13: العاصمة | K13: خاصة | L13: نعم | M13: أحيانًا | N13: نادرًا | O13: تأثرت بشكل سلبي | P13: نعم | Q13: تزيد الدافعية | R13: نعم | S13: يعتمد على طريقة الاستخدام | T13: لا | U13: أحيانًا | V13: نادرًا | W13: لا | X13: نعم بشكل كبير | Y13: لا | Z13: أجبت السؤال السابق ب"لا" | AA13: جيدة | AB13: أحيانًا | AC13: ChatGPT;Claude; | AD13: إلى حد ما | AE13: نادرًا | AF13: - | AG13: - | AH13: =(O13='Labeling Rules'!$C$6)*'Labeling Rules'!$D$6+(Q13='Labeling Rules'!$C$7)*'Labeling Rules'!$D$7+(R13='Labeling Rules'!$C$8)*'Labeling Rules'!$D$8+(R13='Labeling Rules'!$C$9)*'Labeling Rules'!$D$9+(P13='Labeling Rules'!$C$10)*'Labeling Rules'!$D$10+(M13='Labeling Rules'!$C$11)*'Labeling Rules'!$D$11+(T13='Labeling Rules'!$C$12)*'Labeling Rules'!$D$12+(U13='Labeling Rules'!$C$13)*'Labeling Rules'!$D$13+(W13='Labeling Rules'!$C$14)*'Labeling Rules'!$D$14+(Y13='Labeling Rules'!$C$15)*'Labeling Rules'!$D$15 -> 4 | AI13: =IF(AH13>='Labeling Rules'!$D$17,1,0) -> 0
... A131: 130 | B131: 46160.36 | C131: 46160.362 | D131: anonymous | F131: ذكر | G131: تخصصات هندسية وتقنية | H131: بكالوريوس | I131: الخامسة فأعلى | J131: لواء | K131: حكومية | L131: نعم | M131: دائمًا | N131: أحيانًا | O131: تأثرت بشكل إيجابي | P131: نعم | Q131: تزيد الدافعية | R131: لا | S131: لا | T131: لا | U131: دائمًا | V131: أحيانًا | W131: لا | X131: نعم بشكل كبير | Y131: لا | Z131: أجبت السؤال السابق ب"لا" | AA131: جيدة | AB131: أحيانًا | AC131: Google Gemini;ChatGPT | AD131: نعم | AE131: نادرًا | AF131: . | AG131: . | AH131: =(O131='Labeling Rules'!$C$6)*'Labeling Rules'!$D$6+(Q131='Labeling Rules'!$C$7)*'Labeling Rules'!$D$7+(R131='Labeling Rules'!$C$8)*'Labeling Rules'!$D$8+(R131='Labeling Rules'!$C$9)*'Labeling Rules'!$D$9+(P131='Labeling Rules'!$C$10)*'Labeling Rules'!$D$10+(M131='Labeling Rules'!$C$11)*'Labeling Rules'!$D$11+(T131='Labeling Rules'!$C$12)*'Labeling Rules'!$D$12+(U131='Labeling Rules'!$C$13)*'Labeling Rules'!$D$13+(W131='Labeling Rules'!$C$14)*'Labeling Rules'!$D$14+(Y131='Labeling Rules'!$C$15)*'Labeling Rules'!$D$15 -> 1 | AI131: =IF(AH131>='Labeling Rules'!$D$17,1,0) -> 0
A132: 131 | B132: 46160.433 | C132: 46160.434 | D132: anonymous | F132: انثى | G132: تخصصات هندسية وتقنية | H132: بكالوريوس | I132: الرابعة | J132: العاصمة | K132: حكومية | L132: نعم | M132: دائمًا | N132: دائمًا | O132: تأثرت بشكل سلبي | P132: إلى حد ما | Q132: لا تؤثر | R132: أحيانًا | S132: لا | T132: لا | U132: دائمًا | V132: نادرًا | W132: لا | X132: إلى حد ما | Y132: لا | Z132: أجبت السؤال السابق ب"لا" | AA132: جيدة | AB132: لا | AC132: ChatGPT | AD132: إلى حد ما | AE132: دائمًا | AH132: =(O132='Labeling Rules'!$C$6)*'Labeling Rules'!$D$6+(Q132='Labeling Rules'!$C$7)*'Labeling Rules'!$D$7+(R132='Labeling Rules'!$C$8)*'Labeling Rules'!$D$8+(R132='Labeling Rules'!$C$9)*'Labeling Rules'!$D$9+(P132='Labeling Rules'!$C$10)*'Labeling Rules'!$D$10+(M132='Labeling Rules'!$C$11)*'Labeling Rules'!$D$11+(T132='Labeling Rules'!$C$12)*'Labeling Rules'!$D$12+(U132='Labeling Rules'!$C$13)*'Labeling Rules'!$D$13+(W132='Labeling Rules'!$C$14)*'Labeling Rules'!$D$14+(Y132='Labeling Rules'!$C$15)*'Labeling Rules'!$D$15 -> 4 | AI132: =IF(AH132>='Labeling Rules'!$D$17,1,0) -> 0
A133: 132 | B133: 46160.572 | C133: 46160.574 | D133: anonymous | F133: ذكر | G133: تخصصات هندسية وتقنية | H133: بكالوريوس | I133: الثانية | J133: العاصمة | K133: حكومية | L133: نعم | M133: أحيانًا | N133: غالبًا | O133: تأثرت بشكل إيجابي | P133: نعم | Q133: لا تؤثر | R133: لا | S133: يعتمد على طريقة الاستخدام | T133: لا | U133: دائمًا | V133: أحيانًا | W133: لا | X133: نعم بشكل كبير | Y133: لا | Z133: أجبت السؤال السابق ب"لا" | AA133: ممتازة | AB133: نعم | AC133: Google Gemini;Claude | AD133: إلى حد ما | AE133: دائمًا | AF133: استخدامها للمساعده فقط وليس للاعتماد الكامل | AG133: نعم | AH133: =(O133='Labeling Rules'!$C$6)*'Labeling Rules'!$D$6+(Q133='Labeling Rules'!$C$7)*'Labeling Rules'!$D$7+(R133='Labeling Rules'!$C$8)*'Labeling Rules'!$D$8+(R133='Labeling Rules'!$C$9)*'Labeling Rules'!$D$9+(P133='Labeling Rules'!$C$10)*'Labeling Rules'!$D$10+(M133='Labeling Rules'!$C$11)*'Labeling Rules'!$D$11+(T133='Labeling Rules'!$C$12)*'Labeling Rules'!$D$12+(U133='Labeling Rules'!$C$13)*'Labeling Rules'!$D$13+(W133='Labeling Rules'!$C$14)*'Labeling Rules'!$D$14+(Y133='Labeling Rules'!$C$15)*'Labeling Rules'!$D$15 -> 0 | AI133: =IF(AH133>='Labeling Rules'!$D$17,1,0) -> 0
A134: 133 | B134: 46160.581 | C134: 46160.583 | D134: anonymous | F134: ذكر | G134: تخصصات هندسية وتقنية | H134: بكالوريوس | I134: الثانية | J134: العاصمة | K134: حكومية | L134: لا | M134: أحيانًا | N134: أبدًا | O134: تأثرت بشكل إيجابي | P134: نعم | Q134: تزيد الدافعية | R134: أحيانًا | S134: لا | T134: نعم | U134: دائمًا | V134: أحيانًا | W134: لا | X134: نعم بشكل كبير | Y134: لا | Z134: جزئيًا | AA134: جيدة | AB134: أحيانًا | AC134: ChatGPT | AD134: نعم | AE134: أحيانًا | AF134: …… | AG134: …… | AH134: =(O134='Labeling Rules'!$C$6)*'Labeling Rules'!$D$6+(Q134='Labeling Rules'!$C$7)*'Labeling Rules'!$D$7+(R134='Labeling Rules'!$C$8)*'Labeling Rules'!$D$8+(R134='Labeling Rules'!$C$9)*'Labeling Rules'!$D$9+(P134='Labeling Rules'!$C$10)*'Labeling Rules'!$D$10+(M134='Labeling Rules'!$C$11)*'Labeling Rules'!$D$11+(T134='Labeling Rules'!$C$12)*'Labeling Rules'!$D$12+(U134='Labeling Rules'!$C$13)*'Labeling Rules'!$D$13+(W134='Labeling Rules'!$C$14)*'Labeling Rules'!$D$14+(Y134='Labeling Rules'!$C$15)*'Labeling Rules'!$D$15 -> 2 | AI134: =IF(AH134>='Labeling Rules'!$D$17,1,0) -> 0
A135: 134 | B135: 46160.595 | C135: 46160.597 | D135: anonymous | F135: ذكر | G135: تخصصات هندسية وتقنية | H135: بكالوريوس | I135: الرابعة | J135: العاصمة | K135: حكومية | L135: نعم | M135: نادرًا | N135: غالبًا | O135: لم تتأثر | P135: إلى حد ما | Q135: لا تؤثر | R135: لا | S135: لا | T135: لا | U135: دائمًا | V135: أحيانًا | W135: لا | X135: إلى حد ما | Y135: لا | Z135: أجبت السؤال السابق ب"لا" | AA135: جيدة | AB135: نعم | AC135: Claude;ChatGPT | AD135: نعم | AE135: أحيانًا | AF135: . | AG135: . | AH135: =(O135='Labeling Rules'!$C$6)*'Labeling Rules'!$D$6+(Q135='Labeling Rules'!$C$7)*'Labeling Rules'!$D$7+(R135='Labeling Rules'!$C$8)*'Labeling Rules'!$D$8+(R135='Labeling Rules'!$C$9)*'Labeling Rules'!$D$9+(P135='Labeling Rules'!$C$10)*'Labeling Rules'!$D$10+(M135='Labeling Rules'!$C$11)*'Labeling Rules'!$D$11+(T135='Labeling Rules'!$C$12)*'Labeling Rules'!$D$12+(U135='Labeling Rules'!$C$13)*'Labeling Rules'!$D$13+(W135='Labeling Rules'!$C$14)*'Labeling Rules'!$D$14+(Y135='Labeling Rules'!$C$15)*'Labeling Rules'!$D$15 -> 0 | AI135: =IF(AH135>='Labeling Rules'!$D$17,1,0) -> 0
A136: 135 | B136: 46160.594 | C136: 46160.597 | D136: anonymous | F136: انثى | G136: تخصصات هندسية وتقنية | H136: بكالوريوس | I136: الرابعة | J136: العاصمة | K136: حكومية | L136: نعم | M136: دائمًا | N136: دائمًا | O136: تأثرت بشكل سلبي | P136: إلى حد ما | Q136: لا تؤثر | R136: نعم | S136: لا | T136: نعم | U136: دائمًا | V136: كثيرًا | W136: لا | X136: نعم بشكل كبير | Y136: لا | Z136: أجبت السؤال السابق ب"لا" | AA136: ضعيفة | AB136: نعم | AC136: ChatGPT | AD136: نعم | AE136: دائمًا | AF136: . | AG136: يس | AH136: =(O136='Labeling Rules'!$C$6)*'Labeling Rules'!$D$6+(Q136='Labeling Rules'!$C$7)*'Labeling Rules'!$D$7+(R136='Labeling Rules'!$C$8)*'Labeling Rules'!$D$8+(R136='Labeling Rules'!$C$9)*'Labeling Rules'!$D$9+(P136='Labeling Rules'!$C$10)*'Labeling Rules'!$D$10+(M136='Labeling Rules'!$C$11)*'Labeling Rules'!$D$11+(T136='Labeling Rules'!$C$12)*'Labeling Rules'!$D$12+(U136='Labeling Rules'!$C$13)*'Labeling Rules'!$D$13+(W136='Labeling Rules'!$C$14)*'Labeling Rules'!$D$14+(Y136='Labeling Rules'!$C$15)*'Labeling Rules'!$D$15 -> 6 | AI136: =IF(AH136>='Labeling Rules'!$D$17,1,0) -> 1
A137: 136 | B137: 46160.603 | C137: 46160.613 | D137: anonymous | F137: انثى | G137: تخصصات هندسية وتقنية | H137: بكالوريوس | I137: الرابعة | J137: العاصمة | K137: حكومية | L137: نعم | M137: غالبًا | N137: غالبًا | O137: تأثرت بشكل سلبي | P137: إلى حد ما | Q137: تقلل الدافعية | R137: نعم | S137: يعتمد على طريقة الاستخدام | T137: لا | U137: دائمًا | V137: أحيانًا | W137: لا | X137: إلى حد ما | Y137: نعم | Z137: جزئيًا | AA137: جيدة | AB137: أحيانًا | AC137: Google Gemini | AD137: إلى حد ما | AE137: دائمًا | AF137: عدم الاعتماد الكلي طلب منه عدم المبالغة بالمدح والدخول لصلب الموضوع مباشرة | AG137: نوعًا ما | AH137: =(O137='Labeling Rules'!$C$6)*'Labeling Rules'!$D$6+(Q137='Labeling Rules'!$C$7)*'Labeling Rules'!$D$7+(R137='Labeling Rules'!$C$8)*'Labeling Rules'!$D$8+(R137='Labeling Rules'!$C$9)*'Labeling Rules'!$D$9+(P137='Labeling Rules'!$C$10)*'Labeling Rules'!$D$10+(M137='Labeling Rules'!$C$11)*'Labeling Rules'!$D$11+(T137='Labeling Rules'!$C$12)*'Labeling Rules'!$D$12+(U137='Labeling Rules'!$C$13)*'Labeling Rules'!$D$13+(W137='Labeling Rules'!$C$14)*'Labeling Rules'!$D$14+(Y137='Labeling Rules'!$C$15)*'Labeling Rules'!$D$15 -> 7 | AI137: =IF(AH137>='Labeling Rules'!$D$17,1,0) -> 1
A138: 137 | B138: 46160.65 | C138: 46160.652 | D138: anonymous | F138: انثى | G138: تخصصات هندسية وتقنية | H138: بكالوريوس | I138: الرابعة | J138: العاصمة | K138: حكومية | L138: نعم | M138: نادرًا | N138: أبدًا | O138: تأثرت بشكل إيجابي | P138: نعم | Q138: تزيد الدافعية | R138: نعم | S138: يعتمد على طريقة الاستخدام | T138: نعم | U138: أحيانًا | V138: نادرًا | W138: نعم | X138: نعم بشكل كبير | Y138: نعم | Z138: نعم | AA138: متوسطة | AB138: أحيانًا | AC138: Microsoft Copilot | AD138: نعم | AE138: دائمًا | AF138: انتقاء الكلمات ل جعل ال الذكاء كتابه ما تريد | AG138: لا | AH138: =(O138='Labeling Rules'!$C$6)*'Labeling Rules'!$D$6+(Q138='Labeling Rules'!$C$7)*'Labeling Rules'!$D$7+(R138='Labeling Rules'!$C$8)*'Labeling Rules'!$D$8+(R138='Labeling Rules'!$C$9)*'Labeling Rules'!$D$9+(P138='Labeling Rules'!$C$10)*'Labeling Rules'!$D$10+(M138='Labeling Rules'!$C$11)*'Labeling Rules'!$D$11+(T138='Labeling Rules'!$C$12)*'Labeling Rules'!$D$12+(U138='Labeling Rules'!$C$13)*'Labeling Rules'!$D$13+(W138='Labeling Rules'!$C$14)*'Labeling Rules'!$D$14+(Y138='Labeling Rules'!$C$15)*'Labeling Rules'!$D$15 -> 5 | AI138: =IF(AH138>='Labeling Rules'!$D$17,1,0) -> 1
A139: 138 | B139: 46160.858 | C139: 46160.86 | D139: anonymous | F139: انثى | G139: تخصصات هندسية وتقنية | H139: بكالوريوس | I139: الثالثة | J139: العاصمة | K139: حكومية | L139: نعم | M139: نادرًا | N139: نادرًا | O139: لم تتأثر | P139: نعم | Q139: لا تؤثر | R139: لا | S139: يعتمد على طريقة الاستخدام | T139: لا | U139: دائمًا | V139: كثيرًا | W139: لا | X139: إلى حد ما | Y139: لا | Z139: أجبت السؤال السابق ب"لا" | AA139: جيدة | AB139: نعم | AC139: Google Gemini | AD139: لا | AE139: أحيانًا | AF139: عدم الاعتماد عليها اعتماد كلي و استخدامها كأداه للتحسين فقط | AG139: نعم | AH139: =(O139='Labeling Rules'!$C$6)*'Labeling Rules'!$D$6+(Q139='Labeling Rules'!$C$7)*'Labeling Rules'!$D$7+(R139='Labeling Rules'!$C$8)*'Labeling Rules'!$D$8+(R139='Labeling Rules'!$C$9)*'Labeling Rules'!$D$9+(P139='Labeling Rules'!$C$10)*'Labeling Rules'!$D$10+(M139='Labeling Rules'!$C$11)*'Labeling Rules'!$D$11+(T139='Labeling Rules'!$C$12)*'Labeling Rules'!$D$12+(U139='Labeling Rules'!$C$13)*'Labeling Rules'!$D$13+(W139='Labeling Rules'!$C$14)*'Labeling Rules'!$D$14+(Y139='Labeling Rules'!$C$15)*'Labeling Rules'!$D$15 -> 0 | AI139: =IF(AH139>='Labeling Rules'!$D$17,1,0) -> 0
A140: 139 | B140: 46160.92 | C140: 46160.924 | D140: anonymous | F140: ذكر | G140: تخصصات طبية | H140: بكالوريوس | I140: الخامسة فأعلى | J140: العاصمة | K140: حكومية | L140: نعم | M140: أحيانًا | N140: نادرًا | O140: تأثرت بشكل سلبي | P140: نعم | Q140: لا تؤثر | R140: نعم | S140: نعم | T140: لا | U140: دائمًا | V140: كثيرًا | W140: لا | X140: نعم بشكل كبير | Y140: لا | Z140: أجبت السؤال السابق ب"لا" | AA140: ضعيفة | AB140: أحيانًا | AC140: ChatGPT | AD140: لا | AE140: أحيانًا | AF140: عدم الثقة بالنتائج عدم استخدامها كبديل للتفكير ادراك بان الصياغة المقنعة لا تعني الصحة | AG140: ظهرت لي فيديوهات تتحدث عن الموضوع، لم ابحث عن الموضوع متقصدا | AH140: =(O140='Labeling Rules'!$C$6)*'Labeling Rules'!$D$6+(Q140='Labeling Rules'!$C$7)*'Labeling Rules'!$D$7+(R140='Labeling Rules'!$C$8)*'Labeling Rules'!$D$8+(R140='Labeling Rules'!$C$9)*'Labeling Rules'!$D$9+(P140='Labeling Rules'!$C$10)*'Labeling Rules'!$D$10+(M140='Labeling Rules'!$C$11)*'Labeling Rules'!$D$11+(T140='Labeling Rules'!$C$12)*'Labeling Rules'!$D$12+(U140='Labeling Rules'!$C$13)*'Labeling Rules'!$D$13+(W140='Labeling Rules'!$C$14)*'Labeling Rules'!$D$14+(Y140='Labeling Rules'!$C$15)*'Labeling Rules'!$D$15 -> 4 | AI140: =IF(AH140>='Labeling Rules'!$D$17,1,0) -> 0
A141: 140 | B141: 46160.929 | C141: 46160.935 | D141: anonymous | F141: ذكر | G141: تخصصات هندسية وتقنية | H141: بكالوريوس | I141: الخامسة فأعلى | J141: لواء | K141: حكومية | L141: نعم | M141: أحيانًا | N141: أحيانًا | O141: تأثرت بشكل إيجابي | P141: إلى حد ما | Q141: تزيد الدافعية | R141: لا | S141: يعتمد على طريقة الاستخدام | T141: لا | U141: دائمًا | V141: أحيانًا | W141: لا | X141: إلى حد ما | Y141: لا | Z141: أجبت السؤال السابق ب"لا" | AA141: جيدة | AB141: نعم | AC141: Google Gemini | AD141: إلى حد ما | AE141: أحيانًا | AF141: ان لا تكون طريق مختصر وسهل لانشاء النصوص بل وضع اللمسة الخاصة لبناء المشروع مع الاخذ بطرق والمنهجيات كتابة الابحاث والمشاريع وما يشابها من اعمل | AG141: نعم فهو يساعدة في ترتيب الافكار والاقتراحات وتعلم الصيغ الصحيحة لكتابة الابحاث والمشاريع دون الاعتماد الكلي عليها | AH141: =(O141='Labeling Rules'!$C$6)*'Labeling Rules'!$D$6+(Q141='Labeling Rules'!$C$7)*'Labeling Rules'!$D$7+(R141='Labeling Rules'!$C$8)*'Labeling Rules'!$D$8+(R141='Labeling Rules'!$C$9)*'Labeling Rules'!$D$9+(P141='Labeling Rules'!$C$10)*'Labeling Rules'!$D$10+(M141='Labeling Rules'!$C$11)*'Labeling Rules'!$D$11+(T141='Labeling Rules'!$C$12)*'Labeling Rules'!$D$12+(U141='Labeling Rules'!$C$13)*'Labeling Rules'!$D$13+(W141='Labeling Rules'!$C$14)*'Labeling Rules'!$D$14+(Y141='Labeling Rules'!$C$15)*'Labeling Rules'!$D$15 -> 0 | AI141: =IF(AH141>='Labeling Rules'!$D$17,1,0) -> 0
A142: 141 | B142: 46160.939 | C142: 46160.943 | D142: anonymous | F142: ذكر | G142: تخصصات هندسية وتقنية | H142: بكالوريوس | I142: الرابعة | J142: العاصمة | K142: حكومية | L142: نعم | M142: غالبًا | N142: غالبًا | O142: تأثرت بشكل سلبي | P142: نعم | Q142: تزيد الدافعية | R142: أحيانًا | S142: يعتمد على طريقة الاستخدام | T142: لا | U142: دائمًا | V142: كثيرًا | W142: لا | X142: إلى حد ما | Y142: لا | Z142: أجبت السؤال السابق ب"لا" | AA142: متوسطة | AB142: أحيانًا | AC142: ChatGPT | AD142: نعم | AE142: أحيانًا | AF142: الموازنة بين استخدام مهاراتك و تطويرها و استخدام الذكاء الاصطناعي | AG142: لا | AH142: =(O142='Labeling Rules'!$C$6)*'Labeling Rules'!$D$6+(Q142='Labeling Rules'!$C$7)*'Labeling Rules'!$D$7+(R142='Labeling Rules'!$C$8)*'Labeling Rules'!$D$8+(R142='Labeling Rules'!$C$9)*'Labeling Rules'!$D$9+(P142='Labeling Rules'!$C$10)*'Labeling Rules'!$D$10+(M142='Labeling Rules'!$C$11)*'Labeling Rules'!$D$11+(T142='Labeling Rules'!$C$12)*'Labeling Rules'!$D$12+(U142='Labeling Rules'!$C$13)*'Labeling Rules'!$D$13+(W142='Labeling Rules'!$C$14)*'Labeling Rules'!$D$14+(Y142='Labeling Rules'!$C$15)*'Labeling Rules'!$D$15 -> 3 | AI142: =IF(AH142>='Labeling Rules'!$D$17,1,0) -> 0
A143: 142 | B143: 46161.023 | C143: 46161.025 | D143: anonymous | F143: انثى | G143: تخصصات هندسية وتقنية | H143: بكالوريوس | I143: الثانية | J143: العاصمة | K143: حكومية | L143: نعم | M143: دائمًا | N143: دائمًا | O143: تأثرت بشكل سلبي | P143: إلى حد ما | Q143: لا تؤثر | R143: أحيانًا | S143: لا | T143: نعم | U143: دائمًا | V143: كثيرًا | W143: لا | X143: نعم بشكل كبير | Y143: لا | Z143: أجبت السؤال السابق ب"لا" | AA143: متوسطة | AB143: نعم | AC143: Google Gemini;ChatGPT | AD143: إلى حد ما | AE143: دائمًا | AF143: . | AG143: . | AH143: =(O143='Labeling Rules'!$C$6)*'Labeling Rules'!$D$6+(Q143='Labeling Rules'!$C$7)*'Labeling Rules'!$D$7+(R143='Labeling Rules'!$C$8)*'Labeling Rules'!$D$8+(R143='Labeling Rules'!$C$9)*'Labeling Rules'!$D$9+(P143='Labeling Rules'!$C$10)*'Labeling Rules'!$D$10+(M143='Labeling Rules'!$C$11)*'Labeling Rules'!$D$11+(T143='Labeling Rules'!$C$12)*'Labeling Rules'!$D$12+(U143='Labeling Rules'!$C$13)*'Labeling Rules'!$D$13+(W143='Labeling Rules'!$C$14)*'Labeling Rules'!$D$14+(Y143='Labeling Rules'!$C$15)*'Labeling Rules'!$D$15 -> 5 | AI143: =IF(AH143>='Labeling Rules'!$D$17,1,0) -> 1
A144: 143 | B144: 46161.49 | C144: 46161.494 | D144: anonymous | F144: انثى | G144: تخصصات هندسية وتقنية | H144: بكالوريوس | I144: الرابعة | J144: العاصمة | K144: حكومية | L144: نعم | M144: غالبًا | N144: غالبًا | O144: تأثرت بشكل إيجابي | P144: إلى حد ما | Q144: لا تؤثر | R144: أحيانًا | S144: يعتمد على طريقة الاستخدام | T144: لا | U144: دائمًا | V144: أحيانًا | W144: لا | X144: إلى حد ما | Y144: نعم | Z144: جزئيًا | AA144: متوسطة | AB144: أحيانًا | AC144: ChatGPT | AD144: إلى حد ما | AE144: أحيانًا | AF144: . | AG144: . | AH144: =(O144='Labeling Rules'!$C$6)*'Labeling Rules'!$D$6+(Q144='Labeling Rules'!$C$7)*'Labeling Rules'!$D$7+(R144='Labeling Rules'!$C$8)*'Labeling Rules'!$D$8+(R144='Labeling Rules'!$C$9)*'Labeling Rules'!$D$9+(P144='Labeling Rules'!$C$10)*'Labeling Rules'!$D$10+(M144='Labeling Rules'!$C$11)*'Labeling Rules'!$D$11+(T144='Labeling Rules'!$C$12)*'Labeling Rules'!$D$12+(U144='Labeling Rules'!$C$13)*'Labeling Rules'!$D$13+(W144='Labeling Rules'!$C$14)*'Labeling Rules'!$D$14+(Y144='Labeling Rules'!$C$15)*'Labeling Rules'!$D$15 -> 2 | AI144: =IF(AH144>='Labeling Rules'!$D$17,1,0) -> 0
... A166: 165 | B166: 46162.874 | C166: 46162.878 | D166: anonymous | F166: انثى | G166: تخصصات هندسية وتقنية | H166: بكالوريوس | I166: الخامسة فأعلى | J166: محافظة | K166: حكومية | L166: نعم | M166: غالبًا | N166: أحيانًا | O166: تأثرت بشكل سلبي | P166: إلى حد ما | Q166: تقلل الدافعية | R166: أحيانًا | S166: يعتمد على طريقة الاستخدام | T166: لا | U166: دائمًا | V166: كثيرًا | W166: نعم | X166: إلى حد ما | Y166: نعم | Z166: نعم | AA166: متوسطة | AB166: نعم | AC166: ChatGPT;Google Gemini | AD166: لا | AE166: أحيانًا | AF166: Use it to only save time but always double check | AG166: Yes | AH166: =(O166='Labeling Rules'!$C$6)*'Labeling Rules'!$D$6+(Q166='Labeling Rules'!$C$7)*'Labeling Rules'!$D$7+(R166='Labeling Rules'!$C$8)*'Labeling Rules'!$D$8+(R166='Labeling Rules'!$C$9)*'Labeling Rules'!$D$9+(P166='Labeling Rules'!$C$10)*'Labeling Rules'!$D$10+(M166='Labeling Rules'!$C$11)*'Labeling Rules'!$D$11+(T166='Labeling Rules'!$C$12)*'Labeling Rules'!$D$12+(U166='Labeling Rules'!$C$13)*'Labeling Rules'!$D$13+(W166='Labeling Rules'!$C$14)*'Labeling Rules'!$D$14+(Y166='Labeling Rules'!$C$15)*'Labeling Rules'!$D$15 -> 7 | AI166: =IF(AH166>='Labeling Rules'!$D$17,1,0) -> 1
A167: 166 | B167: 46162.885 | C167: 46162.886 | D167: anonymous | F167: انثى | G167: تخصصات علمية | H167: بكالوريوس | I167: الرابعة | J167: محافظة | K167: حكومية | L167: نعم | M167: أحيانًا | N167: أحيانًا | O167: تأثرت بشكل إيجابي | P167: إلى حد ما | Q167: لا تؤثر | R167: أحيانًا | S167: يعتمد على طريقة الاستخدام | T167: لا | U167: أحيانًا | V167: أحيانًا | W167: لا | X167: إلى حد ما | Y167: نعم | Z167: جزئيًا | AA167: متوسطة | AB167: أحيانًا | AC167: Claude | AD167: نعم | AE167: أحيانًا | AH167: =(O167='Labeling Rules'!$C$6)*'Labeling Rules'!$D$6+(Q167='Labeling Rules'!$C$7)*'Labeling Rules'!$D$7+(R167='Labeling Rules'!$C$8)*'Labeling Rules'!$D$8+(R167='Labeling Rules'!$C$9)*'Labeling Rules'!$D$9+(P167='Labeling Rules'!$C$10)*'Labeling Rules'!$D$10+(M167='Labeling Rules'!$C$11)*'Labeling Rules'!$D$11+(T167='Labeling Rules'!$C$12)*'Labeling Rules'!$D$12+(U167='Labeling Rules'!$C$13)*'Labeling Rules'!$D$13+(W167='Labeling Rules'!$C$14)*'Labeling Rules'!$D$14+(Y167='Labeling Rules'!$C$15)*'Labeling Rules'!$D$15 -> 2 | AI167: =IF(AH167>='Labeling Rules'!$D$17,1,0) -> 0
A168: 167 | B168: 46162.881 | C168: 46162.891 | D168: anonymous | F168: انثى | G168: تخصصات علمية | H168: دكتوراه | I168: الأولى | J168: لواء | K168: حكومية | L168: نعم | M168: غالبًا | N168: نادرًا | O168: تأثرت بشكل سلبي | P168: نعم | Q168: تزيد الدافعية | R168: أحيانًا | S168: يعتمد على طريقة الاستخدام | T168: لا | U168: دائمًا | V168: أحيانًا | W168: لا | X168: نعم بشكل كبير | Y168: لا | Z168: أجبت السؤال السابق ب"لا" | AA168: ضعيفة | AB168: أحيانًا | AC168: Claude;Google Gemini | AD168: إلى حد ما | AE168: أحيانًا | AF168: Always check the information you get from reliable sources like journal articles and books. As well as checking it using different AI tools and not depending only on one. | AG168: Yes, after using it I learned that it's better to tailor the task or the question, and input as much details as possible to guarantee the desired results. | AH168: =(O168='Labeling Rules'!$C$6)*'Labeling Rules'!$D$6+(Q168='Labeling Rules'!$C$7)*'Labeling Rules'!$D$7+(R168='Labeling Rules'!$C$8)*'Labeling Rules'!$D$8+(R168='Labeling Rules'!$C$9)*'Labeling Rules'!$D$9+(P168='Labeling Rules'!$C$10)*'Labeling Rules'!$D$10+(M168='Labeling Rules'!$C$11)*'Labeling Rules'!$D$11+(T168='Labeling Rules'!$C$12)*'Labeling Rules'!$D$12+(U168='Labeling Rules'!$C$13)*'Labeling Rules'!$D$13+(W168='Labeling Rules'!$C$14)*'Labeling Rules'!$D$14+(Y168='Labeling Rules'!$C$15)*'Labeling Rules'!$D$15 -> 3 | AI168: =IF(AH168>='Labeling Rules'!$D$17,1,0) -> 0
A169: 168 | B169: 46162.898 | C169: 46162.902 | D169: anonymous | F169: انثى | G169: تخصصات علمية | H169: ماجستير | I169: الثانية | J169: العاصمة | K169: حكومية | L169: نعم | M169: أحيانًا | N169: أحيانًا | O169: تأثرت بشكل سلبي | P169: إلى حد ما | Q169: تزيد الدافعية | R169: أحيانًا | S169: يعتمد على طريقة الاستخدام | T169: لا | U169: دائمًا | V169: أحيانًا | W169: لا | X169: إلى حد ما | Y169: لا | Z169: أجبت السؤال السابق ب"لا" | AA169: متوسطة | AB169: نعم | AC169: ChatGPT | AD169: إلى حد ما | AE169: أحيانًا | AF169: Use it after understanding the topic very well by yourself then use AI just to order your ideas | AG169: Yes | AH169: =(O169='Labeling Rules'!$C$6)*'Labeling Rules'!$D$6+(Q169='Labeling Rules'!$C$7)*'Labeling Rules'!$D$7+(R169='Labeling Rules'!$C$8)*'Labeling Rules'!$D$8+(R169='Labeling Rules'!$C$9)*'Labeling Rules'!$D$9+(P169='Labeling Rules'!$C$10)*'Labeling Rules'!$D$10+(M169='Labeling Rules'!$C$11)*'Labeling Rules'!$D$11+(T169='Labeling Rules'!$C$12)*'Labeling Rules'!$D$12+(U169='Labeling Rules'!$C$13)*'Labeling Rules'!$D$13+(W169='Labeling Rules'!$C$14)*'Labeling Rules'!$D$14+(Y169='Labeling Rules'!$C$15)*'Labeling Rules'!$D$15 -> 3 | AI169: =IF(AH169>='Labeling Rules'!$D$17,1,0) -> 0
A170: 169 | B170: 46162.961 | C170: 46162.965 | D170: anonymous | F170: انثى | G170: تخصصات هندسية وتقنية | H170: بكالوريوس | I170: الرابعة | J170: العاصمة | K170: حكومية | L170: نعم | M170: غالبًا | N170: نادرًا | O170: تأثرت بشكل سلبي | P170: إلى حد ما | Q170: لا تؤثر | R170: أحيانًا | S170: يعتمد على طريقة الاستخدام | T170: نعم | U170: دائمًا | V170: أبدًا | W170: لا | X170: إلى حد ما | Y170: نعم | Z170: جزئيًا | AA170: متوسطة | AB170: أحيانًا | AC170: Claude;Microsoft Copilot;Google Gemini;ChatGPT | AD170: إلى حد ما | AE170: أحيانًا | AF170: المحاوله في التفكير والاجتهاد الشخصي ومن ثم مراجعته مع الذكاء لاعطاء النصائح بعد الاستخدام | AG170: لا | AH170: =(O170='Labeling Rules'!$C$6)*'Labeling Rules'!$D$6+(Q170='Labeling Rules'!$C$7)*'Labeling Rules'!$D$7+(R170='Labeling Rules'!$C$8)*'Labeling Rules'!$D$8+(R170='Labeling Rules'!$C$9)*'Labeling Rules'!$D$9+(P170='Labeling Rules'!$C$10)*'Labeling Rules'!$D$10+(M170='Labeling Rules'!$C$11)*'Labeling Rules'!$D$11+(T170='Labeling Rules'!$C$12)*'Labeling Rules'!$D$12+(U170='Labeling Rules'!$C$13)*'Labeling Rules'!$D$13+(W170='Labeling Rules'!$C$14)*'Labeling Rules'!$D$14+(Y170='Labeling Rules'!$C$15)*'Labeling Rules'!$D$15 -> 5 | AI170: =IF(AH170>='Labeling Rules'!$D$17,1,0) -> 1
A171: 170 | B171: 46162.966 | C171: 46162.972 | D171: anonymous | F171: انثى | G171: تخصصات هندسية وتقنية | H171: بكالوريوس | I171: الخامسة فأعلى | J171: محافظة | K171: حكومية | L171: نعم | M171: غالبًا | N171: دائمًا | O171: لم تتأثر | P171: إلى حد ما | Q171: تزيد الدافعية | R171: نعم | S171: لا | T171: نعم | U171: دائمًا | V171: أحيانًا | W171: لا | X171: نعم بشكل كبير | Y171: لا | Z171: أجبت السؤال السابق ب"لا" | AA171: جيدة | AB171: أحيانًا | AC171: ChatGPT | AD171: نعم | AE171: دائمًا | AF171: always review and edit the generated text before using it | AG171: No | AH171: =(O171='Labeling Rules'!$C$6)*'Labeling Rules'!$D$6+(Q171='Labeling Rules'!$C$7)*'Labeling Rules'!$D$7+(R171='Labeling Rules'!$C$8)*'Labeling Rules'!$D$8+(R171='Labeling Rules'!$C$9)*'Labeling Rules'!$D$9+(P171='Labeling Rules'!$C$10)*'Labeling Rules'!$D$10+(M171='Labeling Rules'!$C$11)*'Labeling Rules'!$D$11+(T171='Labeling Rules'!$C$12)*'Labeling Rules'!$D$12+(U171='Labeling Rules'!$C$13)*'Labeling Rules'!$D$13+(W171='Labeling Rules'!$C$14)*'Labeling Rules'!$D$14+(Y171='Labeling Rules'!$C$15)*'Labeling Rules'!$D$15 -> 3 | AI171: =IF(AH171>='Labeling Rules'!$D$17,1,0) -> 0
A172: 171 | B172: 46163.034 | C172: 46163.035 | D172: anonymous | F172: انثى | G172: تخصصات أدبية/إنسانية | H172: بكالوريوس | I172: الرابعة | J172: العاصمة | K172: حكومية | L172: نعم | M172: غالبًا | N172: أحيانًا | O172: تأثرت بشكل إيجابي | P172: نعم | Q172: تقلل الدافعية | R172: أحيانًا | S172: يعتمد على طريقة الاستخدام | T172: لا | U172: دائمًا | V172: كثيرًا | W172: لا | X172: إلى حد ما | Y172: لا | Z172: أجبت السؤال السابق ب"لا" | AA172: متوسطة | AB172: نعم | AC172: ChatGPT;Google Gemini | AD172: إلى حد ما | AE172: أحيانًا | AF172: . | AG172: . | AH172: =(O172='Labeling Rules'!$C$6)*'Labeling Rules'!$D$6+(Q172='Labeling Rules'!$C$7)*'Labeling Rules'!$D$7+(R172='Labeling Rules'!$C$8)*'Labeling Rules'!$D$8+(R172='Labeling Rules'!$C$9)*'Labeling Rules'!$D$9+(P172='Labeling Rules'!$C$10)*'Labeling Rules'!$D$10+(M172='Labeling Rules'!$C$11)*'Labeling Rules'!$D$11+(T172='Labeling Rules'!$C$12)*'Labeling Rules'!$D$12+(U172='Labeling Rules'!$C$13)*'Labeling Rules'!$D$13+(W172='Labeling Rules'!$C$14)*'Labeling Rules'!$D$14+(Y172='Labeling Rules'!$C$15)*'Labeling Rules'!$D$15 -> 3 | AI172: =IF(AH172>='Labeling Rules'!$D$17,1,0) -> 0
A173: 172 | B173: 46163.253 | C173: 46163.256 | D173: anonymous | F173: انثى | G173: تخصصات علمية | H173: بكالوريوس | I173: الرابعة | J173: محافظة | K173: حكومية | L173: نعم | M173: غالبًا | N173: دائمًا | O173: تأثرت بشكل سلبي | P173: إلى حد ما | Q173: تزيد الدافعية | R173: أحيانًا | S173: لا | T173: لا | U173: دائمًا | V173: أحيانًا | W173: لا | X173: نعم بشكل كبير | Y173: لا | Z173: أجبت السؤال السابق ب"لا" | AA173: جيدة | AB173: أحيانًا | AC173: ChatGPT | AD173: نعم | AE173: نادرًا | AF173: استخدام الذكاء الصناعي بطريقة طرح أو الصياغة فقط ولكن ليس الاعتماد عليه بشكل كلي | AG173: نعم | AH173: =(O173='Labeling Rules'!$C$6)*'Labeling Rules'!$D$6+(Q173='Labeling Rules'!$C$7)*'Labeling Rules'!$D$7+(R173='Labeling Rules'!$C$8)*'Labeling Rules'!$D$8+(R173='Labeling Rules'!$C$9)*'Labeling Rules'!$D$9+(P173='Labeling Rules'!$C$10)*'Labeling Rules'!$D$10+(M173='Labeling Rules'!$C$11)*'Labeling Rules'!$D$11+(T173='Labeling Rules'!$C$12)*'Labeling Rules'!$D$12+(U173='Labeling Rules'!$C$13)*'Labeling Rules'!$D$13+(W173='Labeling Rules'!$C$14)*'Labeling Rules'!$D$14+(Y173='Labeling Rules'!$C$15)*'Labeling Rules'!$D$15 -> 3 | AI173: =IF(AH173>='Labeling Rules'!$D$17,1,0) -> 0
A174: 173 | B174: 46163.31 | C174: 46163.315 | D174: anonymous | F174: انثى | G174: تخصصات هندسية وتقنية | H174: بكالوريوس | I174: الرابعة | J174: محافظة | K174: حكومية | L174: نعم | M174: نادرًا | N174: أحيانًا | O174: تأثرت بشكل إيجابي | P174: إلى حد ما | Q174: لا تؤثر | R174: نعم | S174: يعتمد على طريقة الاستخدام | T174: نعم | U174: دائمًا | V174: كثيرًا | W174: لا | X174: إلى حد ما | Y174: لا | Z174: أجبت السؤال السابق ب"لا" | AA174: متوسطة | AB174: أحيانًا | AC174: ChatGPT | AD174: إلى حد ما | AE174: أحيانًا | AF174: استخدامه للمساعدة وتطوير الأفكار وليس للغش | AG174: نعم، لأن صياغة السؤال بوضوح ودقة تساعد في الحصول على إجابات أفضل من أدوات الذكاء الاصطناعي. | AH174: =(O174='Labeling Rules'!$C$6)*'Labeling Rules'!$D$6+(Q174='Labeling Rules'!$C$7)*'Labeling Rules'!$D$7+(R174='Labeling Rules'!$C$8)*'Labeling Rules'!$D$8+(R174='Labeling Rules'!$C$9)*'Labeling Rules'!$D$9+(P174='Labeling Rules'!$C$10)*'Labeling Rules'!$D$10+(M174='Labeling Rules'!$C$11)*'Labeling Rules'!$D$11+(T174='Labeling Rules'!$C$12)*'Labeling Rules'!$D$12+(U174='Labeling Rules'!$C$13)*'Labeling Rules'!$D$13+(W174='Labeling Rules'!$C$14)*'Labeling Rules'!$D$14+(Y174='Labeling Rules'!$C$15)*'Labeling Rules'!$D$15 -> 3 | AI174: =IF(AH174>='Labeling Rules'!$D$17,1,0) -> 0
A175: 174 | B175: 46163.793 | C175: 46163.794 | D175: anonymous | F175: انثى | G175: تخصصات علمية | H175: ماجستير | I175: الثانية | J175: محافظة | K175: حكومية | L175: نعم | M175: أحيانًا | N175: أحيانًا | O175: تأثرت بشكل إيجابي | P175: إلى حد ما | Q175: تقلل الدافعية | R175: أحيانًا | S175: يعتمد على طريقة الاستخدام | T175: لا | U175: أحيانًا | V175: أحيانًا | W175: لا | X175: إلى حد ما | Y175: لا | Z175: أجبت السؤال السابق ب"لا" | AA175: متوسطة | AB175: أحيانًا | AC175: ChatGPT | AD175: إلى حد ما | AE175: أحيانًا | AF175: ... | AG175: .. | AH175: =(O175='Labeling Rules'!$C$6)*'Labeling Rules'!$D$6+(Q175='Labeling Rules'!$C$7)*'Labeling Rules'!$D$7+(R175='Labeling Rules'!$C$8)*'Labeling Rules'!$D$8+(R175='Labeling Rules'!$C$9)*'Labeling Rules'!$D$9+(P175='Labeling Rules'!$C$10)*'Labeling Rules'!$D$10+(M175='Labeling Rules'!$C$11)*'Labeling Rules'!$D$11+(T175='Labeling Rules'!$C$12)*'Labeling Rules'!$D$12+(U175='Labeling Rules'!$C$13)*'Labeling Rules'!$D$13+(W175='Labeling Rules'!$C$14)*'Labeling Rules'!$D$14+(Y175='Labeling Rules'!$C$15)*'Labeling Rules'!$D$15 -> 3 | AI175: =IF(AH175>='Labeling Rules'!$D$17,1,0) -> 0
A176: 175 | B176: 46164.096 | C176: 46164.098 | D176: anonymous | F176: انثى | G176: تخصصات طبية | H176: بكالوريوس | I176: الثالثة | J176: العاصمة | K176: خاصة | L176: نعم | M176: أحيانًا | N176: نادرًا | O176: تأثرت بشكل إيجابي | P176: لا | Q176: تزيد الدافعية | R176: أحيانًا | S176: يعتمد على طريقة الاستخدام | T176: لا | U176: دائمًا | V176: نادرًا | W176: لا | X176: إلى حد ما | Y176: لا | Z176: أجبت السؤال السابق ب"لا" | AA176: متوسطة | AB176: أحيانًا | AC176: ChatGPT;Google Gemini | AD176: إلى حد ما | AE176: نادرًا | AF176: . | AG176: . | AH176: =(O176='Labeling Rules'!$C$6)*'Labeling Rules'!$D$6+(Q176='Labeling Rules'!$C$7)*'Labeling Rules'!$D$7+(R176='Labeling Rules'!$C$8)*'Labeling Rules'!$D$8+(R176='Labeling Rules'!$C$9)*'Labeling Rules'!$D$9+(P176='Labeling Rules'!$C$10)*'Labeling Rules'!$D$10+(M176='Labeling Rules'!$C$11)*'Labeling Rules'!$D$11+(T176='Labeling Rules'!$C$12)*'Labeling Rules'!$D$12+(U176='Labeling Rules'!$C$13)*'Labeling Rules'!$D$13+(W176='Labeling Rules'!$C$14)*'Labeling Rules'!$D$14+(Y176='Labeling Rules'!$C$15)*'Labeling Rules'!$D$15 -> 2 | AI176: =IF(AH176>='Labeling Rules'!$D$17,1,0) -> 0
A177: 176 | B177: 46164.444 | C177: 46164.448 | D177: anonymous | F177: انثى | G177: تخصصات هندسية وتقنية | H177: بكالوريوس | I177: الخامسة فأعلى | J177: العاصمة | K177: حكومية | L177: نعم | M177: غالبًا | N177: غالبًا | O177: تأثرت بشكل إيجابي | P177: نعم | Q177: لا تؤثر | R177: لا | S177: يعتمد على طريقة الاستخدام | T177: لا | U177: دائمًا | V177: أحيانًا | W177: لا | X177: إلى حد ما | Y177: لا | Z177: أجبت السؤال السابق ب"لا" | AA177: جيدة | AB177: أحيانًا | AC177: Google Gemini;ChatGPT | AD177: إلى حد ما | AE177: أحيانًا | AF177: استخدامه بطريق تسهل علي البحث يعني انا شخصيا بستخدمه حتى يساعدني بترتيب الافكار وتسلسلها واكيد براجع المعلومات اللي بتطلعلي وبتاكد من المصادر ومن بعدها بقوم بصياغتها بطريقة تناسب متطلبات البحث او الواجب او الخ (ما لازم ناخد الاشي نسخ ولصق بدون ما نفهم لانه كتير احيانا المعلومات غلط) | AG177: نعم | AH177: =(O177='Labeling Rules'!$C$6)*'Labeling Rules'!$D$6+(Q177='Labeling Rules'!$C$7)*'Labeling Rules'!$D$7+(R177='Labeling Rules'!$C$8)*'Labeling Rules'!$D$8+(R177='Labeling Rules'!$C$9)*'Labeling Rules'!$D$9+(P177='Labeling Rules'!$C$10)*'Labeling Rules'!$D$10+(M177='Labeling Rules'!$C$11)*'Labeling Rules'!$D$11+(T177='Labeling Rules'!$C$12)*'Labeling Rules'!$D$12+(U177='Labeling Rules'!$C$13)*'Labeling Rules'!$D$13+(W177='Labeling Rules'!$C$14)*'Labeling Rules'!$D$14+(Y177='Labeling Rules'!$C$15)*'Labeling Rules'!$D$15 -> 0 | AI177: =IF(AH177>='Labeling Rules'!$D$17,1,0) -> 0
A178: 177 | B178: 46164.534 | C178: 46164.535 | D178: anonymous | F178: ذكر | G178: تخصصات هندسية وتقنية | H178: بكالوريوس | I178: الخامسة فأعلى | J178: العاصمة | K178: حكومية | L178: نعم | M178: غالبًا | N178: غالبًا | O178: لم تتأثر | P178: إلى حد ما | Q178: لا تؤثر | R178: أحيانًا | S178: لا | T178: نعم | U178: أحيانًا | V178: أحيانًا | W178: لا | X178: نعم بشكل كبير | Y178: لا | Z178: أجبت السؤال السابق ب"لا" | AA178: ممتازة | AB178: نعم | AC178: Claude | AD178: لا | AE178: أحيانًا | AF178: - | AG178: - | AH178: =(O178='Labeling Rules'!$C$6)*'Labeling Rules'!$D$6+(Q178='Labeling Rules'!$C$7)*'Labeling Rules'!$D$7+(R178='Labeling Rules'!$C$8)*'Labeling Rules'!$D$8+(R178='Labeling Rules'!$C$9)*'Labeling Rules'!$D$9+(P178='Labeling Rules'!$C$10)*'Labeling Rules'!$D$10+(M178='Labeling Rules'!$C$11)*'Labeling Rules'!$D$11+(T178='Labeling Rules'!$C$12)*'Labeling Rules'!$D$12+(U178='Labeling Rules'!$C$13)*'Labeling Rules'!$D$13+(W178='Labeling Rules'!$C$14)*'Labeling Rules'!$D$14+(Y178='Labeling Rules'!$C$15)*'Labeling Rules'!$D$15 -> 2 | AI178: =IF(AH178>='Labeling Rules'!$D$17,1,0) -> 0
...

Sheet Labeling Rules
A1: IMPORTANT: Drop_Class_Label is a RULE-BASED PROXY, not observed data.
A2: No respondent was asked whether they dropped a class. The label is derived from self-reported AI-use answers using the rules below.
A3: A model trained to predict this label from the same survey columns will mostly re-learn these rules.
A5: Rule | B5: Column | C5: Answer | D5: Points
A6: Analytical skills affected | B6: O | C6: تأثرت بشكل سلبي | D6: 2
A7: Motivation | B7: Q | C7: تقلل الدافعية | D7: 2
A8: Over-reliance on AI | B8: R | C8: نعم | D8: 2
A9: Over-reliance on AI | B9: R | C9: أحيانًا | D9: 1
A10: Helps independent learning | B10: P | C10: لا | D10: 1
A11: AI use frequency for study | B11: M | C11: دائمًا | D11: 1
A12: Submitted full project with AI | B12: T | C12: نعم | D12: 1
A13: Reviews AI content | B13: U | C13: لا | D13: 1
A14: Used AI in in-class exam | B14: W | C14: نعم | D14: 1
A15: Flagged by a professor | B15: Y | C15: نعم | D15: 1
A17: Threshold (score >= this → label 1) | D17: 5
A18: Max possible score | D18: 11
A20: Rows labeled 1 | D20: =COUNTIF(Sheet1!AI2:AI184,1) -> 50
A21: Rows labeled 0 | D21: =COUNTIF(Sheet1!AI2:AI184,0) -> 133
A22: Share labeled 1 | D22: =D20/(D20+D21) -> 0.27322404
